{
 "cells": [
  {
   "cell_type": "code",
   "execution_count": 1,
   "metadata": {},
   "outputs": [],
   "source": [
    "import io"
   ]
  },
  {
   "cell_type": "code",
   "execution_count": 3,
   "metadata": {},
   "outputs": [],
   "source": [
    "import boto3\n",
    "import csv"
   ]
  },
  {
   "cell_type": "code",
   "execution_count": 4,
   "metadata": {},
   "outputs": [],
   "source": [
    "s3_client = boto3.client('s3')"
   ]
  },
  {
   "cell_type": "code",
   "execution_count": 14,
   "metadata": {},
   "outputs": [
    {
     "ename": "ClientError",
     "evalue": "An error occurred (InvalidAccessKeyId) when calling the GetObject operation: The AWS Access Key Id you provided does not exist in our records.",
     "output_type": "error",
     "traceback": [
      "\u001b[1;31m---------------------------------------------------------------------------\u001b[0m",
      "\u001b[1;31mClientError\u001b[0m                               Traceback (most recent call last)",
      "\u001b[1;32m<ipython-input-14-17f12027e4a3>\u001b[0m in \u001b[0;36m<module>\u001b[1;34m\u001b[0m\n\u001b[1;32m----> 1\u001b[1;33m \u001b[0ms3_object\u001b[0m \u001b[1;33m=\u001b[0m \u001b[0ms3_client\u001b[0m\u001b[1;33m.\u001b[0m\u001b[0mget_object\u001b[0m\u001b[1;33m(\u001b[0m\u001b[0mBucket\u001b[0m\u001b[1;33m=\u001b[0m \u001b[1;34m'baaz-cloud-task'\u001b[0m\u001b[1;33m,\u001b[0m \u001b[0mKey\u001b[0m\u001b[1;33m=\u001b[0m \u001b[1;34m'Cloud_task_file.txt'\u001b[0m\u001b[1;33m)\u001b[0m\u001b[1;33m\u001b[0m\u001b[1;33m\u001b[0m\u001b[0m\n\u001b[0m\u001b[0;32m      2\u001b[0m \u001b[0mdata\u001b[0m \u001b[1;33m=\u001b[0m \u001b[0ms3_object\u001b[0m\u001b[1;33m[\u001b[0m\u001b[1;34m'Body'\u001b[0m\u001b[1;33m]\u001b[0m\u001b[1;33m.\u001b[0m\u001b[0mread\u001b[0m\u001b[1;33m(\u001b[0m\u001b[1;33m)\u001b[0m\u001b[1;33m.\u001b[0m\u001b[0mdecode\u001b[0m\u001b[1;33m(\u001b[0m\u001b[1;34m'utf-8'\u001b[0m\u001b[1;33m)\u001b[0m\u001b[1;33m\u001b[0m\u001b[1;33m\u001b[0m\u001b[0m\n",
      "\u001b[1;32m~\\Anaconda3\\lib\\site-packages\\botocore\\client.py\u001b[0m in \u001b[0;36m_api_call\u001b[1;34m(self, *args, **kwargs)\u001b[0m\n\u001b[0;32m    389\u001b[0m                     \"%s() only accepts keyword arguments.\" % py_operation_name)\n\u001b[0;32m    390\u001b[0m             \u001b[1;31m# The \"self\" in this scope is referring to the BaseClient.\u001b[0m\u001b[1;33m\u001b[0m\u001b[1;33m\u001b[0m\u001b[1;33m\u001b[0m\u001b[0m\n\u001b[1;32m--> 391\u001b[1;33m             \u001b[1;32mreturn\u001b[0m \u001b[0mself\u001b[0m\u001b[1;33m.\u001b[0m\u001b[0m_make_api_call\u001b[0m\u001b[1;33m(\u001b[0m\u001b[0moperation_name\u001b[0m\u001b[1;33m,\u001b[0m \u001b[0mkwargs\u001b[0m\u001b[1;33m)\u001b[0m\u001b[1;33m\u001b[0m\u001b[1;33m\u001b[0m\u001b[0m\n\u001b[0m\u001b[0;32m    392\u001b[0m \u001b[1;33m\u001b[0m\u001b[0m\n\u001b[0;32m    393\u001b[0m         \u001b[0m_api_call\u001b[0m\u001b[1;33m.\u001b[0m\u001b[0m__name__\u001b[0m \u001b[1;33m=\u001b[0m \u001b[0mstr\u001b[0m\u001b[1;33m(\u001b[0m\u001b[0mpy_operation_name\u001b[0m\u001b[1;33m)\u001b[0m\u001b[1;33m\u001b[0m\u001b[1;33m\u001b[0m\u001b[0m\n",
      "\u001b[1;32m~\\Anaconda3\\lib\\site-packages\\botocore\\client.py\u001b[0m in \u001b[0;36m_make_api_call\u001b[1;34m(self, operation_name, api_params)\u001b[0m\n\u001b[0;32m    717\u001b[0m             \u001b[0merror_code\u001b[0m \u001b[1;33m=\u001b[0m \u001b[0mparsed_response\u001b[0m\u001b[1;33m.\u001b[0m\u001b[0mget\u001b[0m\u001b[1;33m(\u001b[0m\u001b[1;34m\"Error\"\u001b[0m\u001b[1;33m,\u001b[0m \u001b[1;33m{\u001b[0m\u001b[1;33m}\u001b[0m\u001b[1;33m)\u001b[0m\u001b[1;33m.\u001b[0m\u001b[0mget\u001b[0m\u001b[1;33m(\u001b[0m\u001b[1;34m\"Code\"\u001b[0m\u001b[1;33m)\u001b[0m\u001b[1;33m\u001b[0m\u001b[1;33m\u001b[0m\u001b[0m\n\u001b[0;32m    718\u001b[0m             \u001b[0merror_class\u001b[0m \u001b[1;33m=\u001b[0m \u001b[0mself\u001b[0m\u001b[1;33m.\u001b[0m\u001b[0mexceptions\u001b[0m\u001b[1;33m.\u001b[0m\u001b[0mfrom_code\u001b[0m\u001b[1;33m(\u001b[0m\u001b[0merror_code\u001b[0m\u001b[1;33m)\u001b[0m\u001b[1;33m\u001b[0m\u001b[1;33m\u001b[0m\u001b[0m\n\u001b[1;32m--> 719\u001b[1;33m             \u001b[1;32mraise\u001b[0m \u001b[0merror_class\u001b[0m\u001b[1;33m(\u001b[0m\u001b[0mparsed_response\u001b[0m\u001b[1;33m,\u001b[0m \u001b[0moperation_name\u001b[0m\u001b[1;33m)\u001b[0m\u001b[1;33m\u001b[0m\u001b[1;33m\u001b[0m\u001b[0m\n\u001b[0m\u001b[0;32m    720\u001b[0m         \u001b[1;32melse\u001b[0m\u001b[1;33m:\u001b[0m\u001b[1;33m\u001b[0m\u001b[1;33m\u001b[0m\u001b[0m\n\u001b[0;32m    721\u001b[0m             \u001b[1;32mreturn\u001b[0m \u001b[0mparsed_response\u001b[0m\u001b[1;33m\u001b[0m\u001b[1;33m\u001b[0m\u001b[0m\n",
      "\u001b[1;31mClientError\u001b[0m: An error occurred (InvalidAccessKeyId) when calling the GetObject operation: The AWS Access Key Id you provided does not exist in our records."
     ]
    }
   ],
   "source": [
    "s3_object = s3_client.get_object(Bucket= 'baaz-cloud-task', Key= 'Cloud_task_file.txt')\n",
    "data = s3_object['Body'].read().decode('utf-8')"
   ]
  },
  {
   "cell_type": "code",
   "execution_count": 12,
   "metadata": {},
   "outputs": [],
   "source": [
    "import boto3\n",
    "client = boto3.client(\n",
    "'s3',\n",
    "aws_access_key_id='AKIAZB5UKEFLWHRWD4MY',\n",
    "aws_secret_access_key='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')"
   ]
  },
  {
   "cell_type": "code",
   "execution_count": null,
   "metadata": {},
   "outputs": [],
   "source": []
  }
 ],
 "metadata": {
  "kernelspec": {
   "display_name": "Python 3",
   "language": "python",
   "name": "python3"
  },
  "language_info": {
   "codemirror_mode": {
    "name": "ipython",
    "version": 3
   },
   "file_extension": ".py",
   "mimetype": "text/x-python",
   "name": "python",
   "nbconvert_exporter": "python",
   "pygments_lexer": "ipython3",
   "version": "3.7.1"
  }
 },
 "nbformat": 4,
 "nbformat_minor": 2
}
